Workbook

Sheet 1.Data
C1: 1G1T1C 1.Data
G2: Matriz ID: | H2: 1g1t1c (G2-T1-C1)
G3: Etapa: | H3: T1 - Diagnóstico Base | K3: Proyecto: | L3: Dossier Analítico NEX_ORD
C4: SIMULACIÓN IN SILICO Datos Anonimizados | G4: Motor Core: | H4: NEX_ORD Platinum v6.0 | K4: Analizado: | L4: 260829_154156
G5: Path Audit: | H5: .../05_Output/FULL_TABLES_1g1t1c.xlsx | K5: Protocolo: | L5: DOI 10.5281/zenodo.189416.1
A7: ► 1.01 DATOS RAW
A9: IDENTIFICACIÓN Y METADATOS | F9: ORDENACION DE ELECCIONES (BREVE) | K9: MORENO | O9: META | Q9: VARIABLES COMPLEMENTARIAS | AA9: ADJETIVOS AAG
A10: Nom | B10: IDi | C10: IDm | D10: Criterio | E10: GRUMO | F10: 1º | G10: 2º | H10: 3º | I10: 4º | J10: 5º | K10: E | L10: R | M10: pE | N10: pR | O10: aE | P10: oE | Q10: SX | R10: ED | S10: ORIG | T10: ANT | U10: ORIEN | V10: IMPL | W10: PRES | X10: ROL | Y10: REND | Z10: COM | AA10: claro | AB10: coherente | AC10: flexible | AD10: consensuado | AE10: productivo | AF10: ordenado | AG10: activo | AH10: ejemplar | AI10: abierto | AJ10: crítico | AK10: perceptivo | AL10: expresivo | AM10: amistoso | AN10: leal | AO10: colaborador | AP10: tolerante
A11: 1 | B11: 1 | C11: 1g1t1c | D11: Tarea | E11: 1 | F11: 1 | G11: 2 | H11: 3 | I11: 4 | J11: 5 | K11: 1, 2 | L11: 5, 4 | M11: 1 | N11: 5 | O11: 1 | P11: 5 | Q11: 1 | R11: 2 | S11: 1 | T11: 2 | U11: 1 | V11: 2 | W11: 1 | X11: 2 | Y11: 3 | Z11: 3 | AA11: 3 | AB11: 3 | AC11: 3 | AD11: 4 | AE11: 3 | AF11: 3 | AG11: 4 | AH11: 3 | AI11: 3 | AJ11: 3 | AK11: 3 | AL11: 3 | AM11: 3 | AN11: 2 | AO11: 2 | AP11: 3
A12: 2 | B12: 2 | C12: 1g1t1c | D12: Tarea | E12: 1 | F12: 3 | G12: 1 | H12: 2 | I12: 5 | J12: 4 | K12: 3, 1 | L12: 4, 5 | M12: 3 | N12: 4 | O12: 3 | P12: 4 | Q12: 2 | R12: 2 | S12: 1 | T12: 2 | U12: 1 | V12: 2 | W12: 1 | X12: 1 | Y12: 2 | Z12: 2 | AA12: 3 | AB12: 3 | AC12: 3 | AD12: 2 | AE12: 4 | AF12: 3 | AG12: 3 | AH12: 2 | AI12: 3 | AJ12: 3 | AK12: 3 | AL12: 3 | AM12: 3 | AN12: 3 | AO12: 3 | AP12: 4
A13: 3 | B13: 3 | C13: 1g1t1c | D13: Tarea | E13: 1 | F13: 2 | G13: 3 | H13: 1 | I13: 5 | J13: 4 | K13: 2, 3 | L13: 4, 5 | M13: 2 | N13: 4 | O13: 2 | P13: 4 | Q13: 1 | R13: 2 | S13: 1 | T13: 2 | U13: 1 | V13: 2 | W13: 1 | X13: 1 | Y13: 2 | Z13: 2 | AA13: 3 | AB13: 3 | AC13: 3 | AD13: 3 | AE13: 3 | AF13: 2 | AG13: 2 | AH13: 3 | AI13: 3 | AJ13: 3 | AK13: 3 | AL13: 3 | AM13: 2 | AN13: 3 | AO13: 3 | AP13: 3
A14: 4 | B14: 4 | C14: 1g1t1c | D14: Tarea | E14: 2 | F14: 4 | G14: 5 | H14: 1 | I14: 2 | J14: 3 | K14: 4, 5 | L14: 3, 2 | M14: 4 | N14: 3 | O14: 4 | P14: 3 | Q14: 2 | R14: 2 | S14: 1 | T14: 2 | U14: 1 | V14: 2 | W14: 1 | X14: 1 | Y14: 2 | Z14: 2 | AA14: 7 | AB14: 6 | AC14: 7 | AD14: 7 | AE14: 7 | AF14: 7 | AG14: 7 | AH14: 7 | AI14: 6 | AJ14: 7 | AK14: 7 | AL14: 7 | AM14: 7 | AN14: 7 | AO14: 6 | AP14: 6
A15: 5 | B15: 5 | C15: 1g1t1c | D15: Tarea | E15: 2 | F15: 5 | G15: 4 | H15: 2 | I15: 3 | J15: 1 | K15: 5, 4 | L15: 1, 3 | M15: 5 | N15: 1 | O15: 5 | P15: 1 | Q15: 1 | R15: 2 | S15: 1 | T15: 2 | U15: 1 | V15: 2 | W15: 1 | X15: 1 | Y15: 2 | Z15: 2 | AA15: 3 | AB15: 4 | AC15: 3 | AD15: 3 | AE15: 3 | AF15: 3 | AG15: 3 | AH15: 4 | AI15: 3 | AJ15: 4 | AK15: 2 | AL15: 3 | AM15: 3 | AN15: 3 | AO15: 3 | AP15: 2
A18: ► 1.02 MATRIZ SMIb instrumental
A20: ID_Sujeto | B20: 1 | C20: 2 | D20: 3 | E20: 4 | F20: 5
A21: 1 | B21: AAAA | C21: 0BB0 | D21: 0000 | E21: 0b00 | F21: aaaa
A22: 2 | B22: 0BB0 | C22: 0000 | D22: AAAA | E22: aaa0 | F22: 0b00
A23: 3 | B23: 0000 | C23: AAAA | D23: 0BB0 | E23: aaaa | F23: 0bb0
A24: 4 | B24: 00c0 | C24: 0baa | D24: aabb | E24: AAAA | F24: 0BB0
A25: 5 | B25: aaaa | C25: 00b0 | D25: 0bc0 | E25: 0BB0 | F25: AAAA
A28: ► 1.03 MATRIZ SMIa integrada | H28: DADAS
A30: SMIa | B30: 1 | C30: 2 | D30: 3 | E30: 4 | F30: 5 | H30: E | I30: ¿ | J30: R | K30: < | L30: ¡ | M30: [
A31: 1 | B31: <Ee> | C31: ¡Ee! | D31: ¡¿?! | E31: ¡R?! | F31: [Rr] | H31: 2 | I31: 1 | J31: 2 | K31: 1 | L31: 3 | M31: 1
A32: 2 | B32: ¡Ee! | C32: <Ee> | D32: <Ee> | E32: [Rr! | F32: ¡R?! | H32: 3 | I32: 0 | J32: 2 | K32: 2 | L32: 2 | M32: 1
A33: 3 | B33: ¡¿?! | C33: <Ee> | D33: ¡Ee! | E33: [Rr] | F33: ¡Rr! | H33: 2 | I33: 1 | J33: 2 | K33: 1 | L33: 3 | M33: 1
A34: 4 | B34: ¡¿r! | C34: ¡Rr] | D34: [Rr] | E34: <Ee> | F34: ¡Ee! | H34: 2 | I34: 1 | J34: 2 | K34: 1 | L34: 3 | M34: 1
A35: 5 | B35: [Rr] | C35: ¡¿r! | D35: ¡Rr! | E35: ¡Ee! | F35: <Ee> | H35: 2 | I35: 1 | J35: 2 | K35: 1 | L35: 3 | M35: 1
G36: SUM | H36: 11 | I36: 4 | J36: 10 | K36: 6 | L36: 14 | M36: 5
A38: Recibidas | B38: 1 | C38: 2 | D38: 3 | E38: 4 | F38: 5 | G38: SUM | I38: SMIa. Explicación
A39: e | B39: 2 | C39: 3 | D39: 2 | E39: 2 | F39: 2 | G39: 11 | J39: DA | L39: RECIBE
A40: ? | B40: 1 | C40: 0 | D40: 1 | E40: 1 | F40: 1 | G40: 4 | I40: tipo | J40: PERCEPCION | K40: REAL | L40: REAL | M40: PERCEPCION
A41: r | B41: 2 | C41: 2 | D41: 2 | E41: 2 | F41: 2 | G41: 10 | I41: elige | J41: < | K41: E | L41: e | M41: >
A42: > | B42: 1 | C42: 2 | D42: 1 | E42: 1 | F42: 1 | G42: 6 | I42: indiferencia | J42: ¡ | K42: ¿ | L42: ? | M42: !
A43: ! | B43: 3 | C43: 2 | D43: 3 | E43: 3 | F43: 3 | G43: 14 | I43: relega | J43: [ | K43: R | L43: r | M43: ]
A44: ] | B44: 1 | C44: 1 | D44: 1 | E44: 1 | F44: 1 | G44: 5
I46: ► 1.05 TOTALES DE GRUPO
A47: ► 1.04 RECUENTOS especiales
J48: % grupales | K48: concepto
A49: Reciprocid | B49: 1 | C49: 2 | D49: 3 | E49: 4 | F49: 5 | G49: SUM | I49: (<)+E | J49: =IFERROR((K$36+H$36)/(K$36+L$36+M$36+H$36+I$36+J$36)*100, 0) -> 34 | K49: Preferencias +
A50: Ee | B50: 2 | C50: 3 | D50: 2 | E50: 2 | F50: 2 | G50: 11 | I50: (¡)+(¿) | J50: =IFERROR((L$36+I$36)/(K$36+L$36+M$36+H$36+I$36+J$36)*100, 0) -> 36 | K50: Indiferencias
...

Sheet 2.SMIa_Frec
C1: 1G1T1C 2.SMIa_Frec
G2: Matriz ID: | H2: 1g1t1c (G2-T1-C1)
G3: Etapa: | H3: T1 - Diagnóstico Base | K3: Proyecto: | L3: Dossier Analítico NEX_ORD
C4: SIMULACIÓN IN SILICO Datos Anonimizados | G4: Motor Core: | H4: NEX_ORD Platinum v6.0 | K4: Analizado: | L4: 260829_154156
G5: Path Audit: | H5: .../05_Output/FULL_TABLES_1g1t1c.xlsx | K5: Protocolo: | L5: DOI 10.5281/zenodo.189416.1
A7: ► 2.01 2.01: SMIa SOCIOMATRIZ RELACIONAL INTEGRADA
A9: SMIa | B9: 1 | C9: 2 | D9: 3 | E9: 4 | F9: 5
A10: 1 | B10: <Ee> | C10: ¡Ee! | D10: ¡¿?! | E10: ¡R?! | F10: [Rr]
A11: 2 | B11: ¡Ee! | C11: <Ee> | D11: <Ee> | E11: [Rr! | F11: ¡R?!
A12: 3 | B12: ¡¿?! | C12: <Ee> | D12: ¡Ee! | E12: [Rr] | F12: ¡Rr!
A13: 4 | B13: ¡¿r! | C13: ¡Rr] | D13: [Rr] | E13: <Ee> | F13: ¡Ee!
A14: 5 | B14: [Rr] | C14: ¡¿r! | D14: ¡Rr! | E14: ¡Ee! | F14: <Ee>
A17: 2.02: NUMERALIZACION FIGURAS
A18: FIGURAS | B18: e> | D18: e! | F18: e] | H18: ?> | J18: ?! | L18: ?] | N18: r> | P18: r! | R18: r]
A19: <E | B19: 81 | C19: <Ee> | D19: 80 | E19: <Ee! | F19: 78 | G19: <Ee] | H19: 75 | I19: <E?> | J19: 71 | K19: <E?! | L19: 66 | M19: <E?] | N19: 60 | O19: <Er> | P19: 53 | Q19: <Er! | R19: 45 | S19: <Er]
A20: ¡E | B20: 79 | C20: ¡Ee> | D20: 77 | E20: ¡Ee! | F20: 74 | G20: ¡Ee] | H20: 70 | I20: ¡E?> | J20: 65 | K20: ¡E?! | L20: 59 | M20: ¡E?] | N20: 52 | O20: ¡Er> | P20: 44 | Q20: ¡Er! | R20: 36 | S20: ¡Er]
A21: [E | B21: 76 | C21: [Ee> | D21: 73 | E21: [Ee! | F21: 69 | G21: [Ee] | H21: 64 | I21: [E?> | J21: 58 | K21: [E?! | L21: 51 | M21: [E?] | N21: 43 | O21: [Er> | P21: 35 | Q21: [Er! | R21: 28 | S21: [Er]
A22: <¿ | B22: 72 | C22: <¿e> | D22: 68 | E22: <¿e! | F22: 63 | G22: <¿e] | H22: 57 | I22: <¿?> | J22: 50 | K22: <¿?! | L22: 42 | M22: <¿?] | N22: 34 | O22: <¿r> | P22: 27 | Q22: <¿r! | R22: 21 | S22: <¿r]
A23: ¡¿ | B23: 67 | C23: ¡¿e> | D23: 62 | E23: ¡¿e! | F23: 56 | G23: ¡¿e] | H23: 49 | I23: ¡¿?> | J23: 41 | K23: ¡¿?! | L23: 33 | M23: ¡¿?] | N23: 26 | O23: ¡¿r> | P23: 20 | Q23: ¡¿r! | R23: 15 | S23: ¡¿r]
A24: [¿ | B24: 61 | C24: [¿e> | D24: 55 | E24: [¿e! | F24: 48 | G24: [¿e] | H24: 40 | I24: [¿?> | J24: 32 | K24: [¿?! | L24: 25 | M24: [¿?] | N24: 19 | O24: [¿r> | P24: 14 | Q24: [¿r! | R24: 10 | S24: [¿r]
A25: <R | B25: 54 | C25: <Re> | D25: 47 | E25: <Re! | F25: 39 | G25: <Re] | H25: 31 | I25: <R?> | J25: 24 | K25: <R?! | L25: 18 | M25: <R?] | N25: 13 | O25: <Rr> | P25: 9 | Q25: <Rr! | R25: 6 | S25: <Rr]
A26: ¡R | B26: 46 | C26: ¡Re> | D26: 38 | E26: ¡Re! | F26: 30 | G26: ¡Re] | H26: 23 | I26: ¡R?> | J26: 17 | K26: ¡R?! | L26: 12 | M26: ¡R?] | N26: 8 | O26: ¡Rr> | P26: 5 | Q26: ¡Rr! | R26: 3 | S26: ¡Rr]
A27: [R | B27: 37 | C27: [Re> | D27: 29 | E27: [Re! | F27: 22 | G27: [Re] | H27: 16 | I27: [R?> | J27: 11 | K27: [R?! | L27: 7 | M27: [R?] | N27: 4 | O27: [Rr> | P27: 2 | Q27: [Rr! | R27: 1 | S27: [Rr]
A30: ► 2.03 MATRIZ FRECUENCIAS | H30: ► 2.04 REORDENACION SMIa NUMERALIZADA
A32: © | B32: 1 | C32: 2 | D32: 3 | E32: 4 | F32: 5 | I32: <Ee> | L32: ¡Ee! | M32: ¡R?!
A33: 1 | B33: 81 | C33: 77 | D33: 41 | E33: 17 | F33: 1 | H33: <Ee> | I33: 81 | J33: 81 | K33: 81 | L33: 77
A34: 2 | B34: 77 | C34: 81 | D34: 81 | E34: 2 | F34: 17 | I34: 81 | J34: 81 | K34: 77 | M34: 17
A35: 3 | B35: 41 | C35: 81 | D35: 77 | E35: 1 | F35: 5 | I35: 81 | J35: 77 | L35: 17 | M35: 3
A36: 4 | B36: 20 | C36: 3 | D36: 1 | E36: 81 | F36: 77 | H36: ¡Ee! | I36: 77 | J36: 20 | K36: 5 | L36: 2 | M36: 1
A37: 5 | B37: 1 | C37: 20 | D37: 5 | E37: 77 | F37: 81 | H37: ¡¿r! | I37: 20 | J37: 5 | K37: 1 | L37: 1 | M37: 1
A41: ► 2.05 TRANSFORMACION DIRECTA SMIa (nxn) -> FIGURAS (9X9) | M41: ► 2.06 CONCENTRACION DIRECTA
A42: FIGURAS | B42: e> | C42: e! | D42: e] | E42: ?> | F42: ?! | G42: ?] | H42: r> | I42: r! | J42: r] | K42: suma | M42: Frec | N42: e! | O42: ?! | P42: r! | Q42: suma
A43: <E | B43: 6 | K43: 6 | M43: ¡E | N43: 11 | Q43: 11
A44: ¡E | C44: 5 | K44: 5 | M44: ¡¿ | O44: 2 | P44: 2 | Q44: 4
A45: [E | M45: ¡R | O45: 2 | P45: 8 | Q45: 10
A46: <¿ | M46: suma | N46: 11 | O46: 4 | P46: 10 | Q46: ►25.
A47: ¡¿ | F47: 2 | I47: 2 | K47: 4
A48: [¿ | M48: % | N48: e! | O48: ?! | P48: r! | Q48: suma
A49: <R | M49: ¡E | N49: 0.44 | Q49: 0.44
A50: ¡R | F50: 2 | I50: 2 | J50: 1 | K50: 5 | M50: ¡¿ | O50: 0.08 | P50: 0.08 | Q50: 0.16
...

Sheet 3.SMIa_Den
C1: 1G1T1C ► 3.SMIa_Den
G2: Matriz ID: | H2: 1g1t1c (G2-T1-C1)
G3: Etapa: | H3: T1 - Diagnóstico Base | K3: Proyecto: | L3: Dossier Analítico NEX_ORD
C4: SIMULACIÓN IN SILICO Datos Anonimizados | G4: Motor Core: | H4: NEX_ORD Platinum v6.0 | K4: Analizado: | L4: 260829_154156
G5: Path Audit: | H5: .../05_Output/FULL_TABLES_1g1t1c.xlsx | K5: Protocolo: | L5: DOI 10.5281/zenodo.189416.1
A7: ► 3.01 SMIa Numerali
A9: © | B9: 1 | D9: 2 | F9: 3 | H9: 4 | J9: 5
A10: 1 | B10: 81 | C10: 1-1 | D10: 77 | E10: 1-2 | F10: 41 | G10: 1-3 | H10: 17 | I10: 1-4 | J10: 1 | K10: 1-5
A11: 2 | B11: 77 | C11: 2-1 | D11: 81 | E11: 2-2 | F11: 81 | G11: 2-3 | H11: 2 | I11: 2-4 | J11: 17 | K11: 2-5
A12: 3 | B12: 41 | C12: 3-1 | D12: 81 | E12: 3-2 | F12: 77 | G12: 3-3 | H12: 1 | I12: 3-4 | J12: 5 | K12: 3-5
A13: 4 | B13: 20 | C13: 4-1 | D13: 3 | E13: 4-2 | F13: 1 | G13: 4-3 | H13: 81 | I13: 4-4 | J13: 77 | K13: 4-5
A14: 5 | B14: 1 | C14: 5-1 | D14: 20 | E14: 5-2 | F14: 5 | G14: 5-3 | H14: 77 | I14: 5-4 | J14: 81 | K14: 5-5
A17: ► 3.02 FIGURAS SOCIOM | M17: ► 3.03 NUMERALIZACION
A19: FIGURAS | B19: e> | C19: e! | D19: e] | E19: ?> | F19: ?! | G19: ?] | H19: r> | I19: r! | J19: r] | M19: FIGURAS | N19: e> | O19: e! | P19: e] | Q19: ?> | R19: ?! | S19: ?] | T19: r> | U19: r! | V19: r]
A20: <E | B20: <Ee> | C20: <Ee! | D20: <Ee] | E20: <E?> | F20: <E?! | G20: <E?] | H20: <Er> | I20: <Er! | J20: <Er] | M20: <E | N20: 81 | O20: 80 | P20: 78 | Q20: 75 | R20: 71 | S20: 66 | T20: 60 | U20: 53 | V20: 45
A21: ¡E | B21: ¡Ee> | C21: ¡Ee! | D21: ¡Ee] | E21: ¡E?> | F21: ¡E?! | G21: ¡E?] | H21: ¡Er> | I21: ¡Er! | J21: ¡Er] | M21: ¡E | N21: 79 | O21: 77 | P21: 74 | Q21: 70 | R21: 65 | S21: 59 | T21: 52 | U21: 44 | V21: 36
A22: [E | B22: [Ee> | C22: [Ee! | D22: [Ee] | E22: [E?> | F22: [E?! | G22: [E?] | H22: [Er> | I22: [Er! | J22: [Er] | M22: [E | N22: 76 | O22: 73 | P22: 69 | Q22: 64 | R22: 58 | S22: 51 | T22: 43 | U22: 35 | V22: 28
A23: <¿ | B23: <¿e> | C23: <¿e! | D23: <¿e] | E23: <¿?> | F23: <¿?! | G23: <¿?] | H23: <¿r> | I23: <¿r! | J23: <¿r] | M23: <¿ | N23: 72 | O23: 68 | P23: 63 | Q23: 57 | R23: 50 | S23: 42 | T23: 34 | U23: 27 | V23: 21
A24: ¡¿ | B24: ¡¿e> | C24: ¡¿e! | D24: ¡¿e] | E24: ¡¿?> | F24: ¡¿?! | G24: ¡¿?] | H24: ¡¿r> | I24: ¡¿r! | J24: ¡¿r] | M24: ¡¿ | N24: 67 | O24: 62 | P24: 56 | Q24: 49 | R24: 41 | S24: 33 | T24: 26 | U24: 20 | V24: 15
A25: [¿ | B25: [¿e> | C25: [¿e! | D25: [¿e] | E25: [¿?> | F25: [¿?! | G25: [¿?] | H25: [¿r> | I25: [¿r! | J25: [¿r] | M25: [¿ | N25: 61 | O25: 55 | P25: 48 | Q25: 40 | R25: 32 | S25: 25 | T25: 19 | U25: 14 | V25: 10
A26: <R | B26: <Re> | C26: <Re! | D26: <Re] | E26: <R?> | F26: <R?! | G26: <R?] | H26: <Rr> | I26: <Rr! | J26: <Rr] | M26: <R | N26: 54 | O26: 47 | P26: 39 | Q26: 31 | R26: 24 | S26: 18 | T26: 13 | U26: 9 | V26: 6
A27: ¡R | B27: ¡Re> | C27: ¡Re! | D27: ¡Re] | E27: ¡R?> | F27: ¡R?! | G27: ¡R?] | H27: ¡Rr> | I27: ¡Rr! | J27: ¡Rr] | M27: ¡R | N27: 46 | O27: 38 | P27: 30 | Q27: 23 | R27: 17 | S27: 12 | T27: 8 | U27: 5 | V27: 3
A28: [R | B28: [Re> | C28: [Re! | D28: [Re] | E28: [R?> | F28: [R?! | G28: [R?] | H28: [Rr> | I28: [Rr! | J28: [Rr] | M28: [R | N28: 37 | O28: 29 | P28: 22 | Q28: 16 | R28: 11 | S28: 7 | T28: 4 | U28: 2 | V28: 1
A31: ► 3.04 TRANSFORMACION | M31: ► 3.05 SUJETOS EN CADA CELDA
A33: FIGURA | B33: e> | C33: e! | D33: e] | E33: ?> | F33: ?! | G33: ?] | H33: r> | I33: r! | J33: r] | K33: suma | M33: ► 3.07 TRANSFORMACION INVERSA SMIa (nxn) -> FIGURAS (9X9) FRECUENCIAS
A34: <E | B34: 6 | K34: 6 | M34: 77 | N34: 1-2 | O34: 2-1 | P34: 3-3 | Q34: 4-5 | R34: 5-4
A35: ¡E | C35: 5 | K35: 5 | M35: FIGURA | N35: e> | O35: ?> | P35: r> | Q35: e! | R35: ?! | S35: r! | T35: e] | U35: ?] | V35: r] | W35: suma
A36: [E | M36: <E | N36: 6 | W36: 6
A37: <¿ | M37: <¿
A38: ¡¿ | F38: 2 | I38: 2 | K38: 4 | M38: <R
A39: [¿ | M39: ¡E | Q39: 5 | W39: 5
A40: <R | M40: ¡¿ | R40: 2 | S40: 2 | W40: 4
A41: ¡R | F41: 2 | I41: 2 | J41: 1 | K41: 5 | M41: ¡R | R41: 2 | S41: 2 | V41: 1 | W41: 5
A42: [R | I42: 1 | J42: 4 | K42: 5 | M42: [E
A43: suma | B43: 6 | C43: 5 | F43: 4 | I43: 5 | J43: 5 | K43: 25 | M43: [¿
M44: [R | S44: 1 | V44: 4 | W44: 5
A45: ► 3.06 3x3 DIRECTA FRECUENCIAS | M45: suma | N45: 6 | Q45: 5 | R45: 4 | S45: 5 | V45: 5 | W45: 25
A47: Frec | B47: e! | C47: ?! | D47: r! | E47: suma | M47: ► 3.08 3x3 INVERSA FRECUENCIAS
A48: ¡E | B48: 11 | E48: 11
A49: ¡¿ | C49: 2 | D49: 2 | E49: 4 | M49: Frec | N49: e! | O49: ?! | P49: r! | Q49: suma
...

Sheet 4.Densidad
C1: 1G1T1C DENSIDAD RELACIONAL
G2: Matriz ID: | H2: 1g1t1c (G2-T1-C1)
G3: Etapa: | H3: T1 - Diagnóstico Base | K3: Proyecto: | L3: Dossier Analítico NEX_ORD
C4: SIMULACIÓN IN SILICO Datos Anonimizados | G4: Motor Core: | H4: NEX_ORD Platinum v6.0 | K4: Analizado: | L4: 260829_154156
G5: Path Audit: | H5: .../05_Output/FULL_TABLES_1g1t1c.xlsx | K5: Protocolo: | L5: DOI 10.5281/zenodo.189416.1
A7: ► TABLA MAESTRA SÍNTESIS DENSIDAD RELACIONAL
F8: A1+A2 | G8: SRC-SDA | H8: A3+A4 | I8: SDA+SRC | J8: |A1|+|A2| | K8: BRC-BDA | L8: |A3|+|A4| | M8: BDA+BRC | N8: BDR-SDR
A9: 1g1t2c | B9: A1 | C9: A2 | D9: A3 | E9: A4 | F9: SDA | G9: Dif | H9: SRC | I9: SDR | J9: BDA | K9: Dif | L9: BRC | M9: BDR | N9: Dif_DR
A10: 1 | B10: 1.83 | C10: -1.92 | D10: -2.025 | E10: 1.83 | F10: =B10+C10 -> -0.09 | G10: =H10-F10 -> -0.105 | H10: =D10+E10 -> -0.195 | I10: =F10+H10 -> -0.285 | J10: 17.81 | K10: =L10-J10 -> 0.105 | L10: 17.915 | M10: =J10+L10 -> 35.725 | N10: =M10-I10 -> 36.01
A11: 2 | B11: 2.32 | C11: -1.735 | D11: -1.71 | E11: 2.255 | F11: =B11+C11 -> 0.585 | G11: =H11-F11 -> -0.04 | H11: =D11+E11 -> 0.545 | I11: =F11+H11 -> 1.13 | J11: 17.135 | K11: =L11-J11 -> 0.04 | L11: 17.175 | M11: =J11+L11 -> 34.31 | N11: =M11-I11 -> 33.18
A12: 3 | B12: 1.24 | C12: -3.04 | D12: -3.1 | E12: 1.235 | F12: =B12+C12 -> -1.8 | G12: =H12-F12 -> -0.065 | H12: =D12+E12 -> -1.865 | I12: =F12+H12 -> -3.665 | J12: 19.52 | K12: =L12-J12 -> 0.065 | L12: 19.585 | M12: =J12+L12 -> 39.105 | N12: =M12-I12 -> 42.77
A13: 4 | B13: -0.88 | C13: -4.945 | D13: -5 | E13: -0.95 | F13: =B13+C13 -> -5.825 | G13: =H13-F13 -> -0.125 | H13: =D13+E13 -> -5.95 | I13: =F13+H13 -> -11.775 | J13: 23.545 | K13: =L13-J13 -> 0.125 | L13: 23.67 | M13: =J13+L13 -> 47.215 | N13: =M13-I13 -> 58.99
A14: 5 | B14: 0.57 | C14: -4.64 | D14: -4.725 | E14: 0.57 | F14: =B14+C14 -> -4.07 | G14: =H14-F14 -> -0.085 | H14: =D14+E14 -> -4.155 | I14: =F14+H14 -> -8.225 | J14: 21.79 | K14: =L14-J14 -> 0.085 | L14: 21.875 | M14: =J14+L14 -> 43.665 | N14: =M14-I14 -> 51.89
A15: Media | B15: =AVERAGE(B10:B14) -> 1.016 | C15: =AVERAGE(C10:C14) -> -3.256 | D15: =AVERAGE(D10:D14) -> -3.312 | E15: =AVERAGE(E10:E14) -> 0.988 | F15: =AVERAGE(F10:F14) -> -2.24 | G15: =AVERAGE(G10:G14) -> -0.084 | H15: =AVERAGE(H10:H14) -> -2.324 | I15: =AVERAGE(I10:I14) -> -4.564 | ... N15: =AVERAGE(N10:N14) -> 44.568
A18: ► 4.01 GRUPO A1-A4 pE/R, E/R, e/r, pe/r | L18: ► 4.02 RESUMEN DE DENSIDADES
A20: A1 | B20: 1 | C20: 2 | D20: 3 | E20: 4 | F20: 5 | G20: SUMA | H20: MEDIA | I20: DT | J20: %_PESO | L20: RESUMEN | M20: SUMA | N20: MEDIA | O20: DT | P20: %_PESO
A21: 1 | B21: 4.44 | C21: 1.26 | D21: 0 | E21: -0.71 | F21: -3.2 | G21: 1.79 | H21: 0.358 | I21: 2.801985 | J21: 35.23622 | L21: A1 | M21: 5.08 | N21: 0.2032 | O21: 2.578638 | P21: 11.852543
A22: 2 | B22: 1.26 | C22: 0 | D22: 4.44 | E22: -2.97 | F22: -0.71 | G22: 2.02 | H22: 0.404 | I22: 2.7299322 | J22: 39.76378 | L22: A2 | M22: -16.28 | N22: -0.6512 | O22: 2.2628218 | P22: -37.984134
A23: 3 | B23: 0 | C23: 4.44 | D23: 1.26 | E23: -3.2 | F23: -1.26 | G23: 1.24 | H23: 0.248 | I23: 2.864493 | J23: 24.409449 | L23: A3 | M23: -16.56 | N23: -0.6624 | O23: 2.2667921 | P23: -38.637424
A24: 4 | B24: -0.63 | C24: -2.45 | D24: -3.2 | E24: 4.44 | F24: 1.26 | G24: -0.58 | H24: -0.116 | I24: 3.0770652 | J24: -11.417323 | L24: A4 | M24: 4.94 | N24: 0.1976 | O24: 2.5841583 | P24: 11.525898
A25: 5 | B25: -3.2 | C25: -0.63 | D25: -1.26 | E25: 1.26 | F25: 4.44 | G25: 0.61 | H25: 0.122 | I25: 2.8918541 | J25: 12.007874
A26: T_COL | B26: 1.87 | C26: 2.62 | D26: 1.24 | E26: -1.18 | F26: 0.53 | G26: 5.08
A27: Media_C | B27: 0.374 | C27: 0.524 | D27: 0.248 | E27: -0.236 | F27: 0.106
A28: DT_C | B28: 2.7945805 | C28: 2.5655272 | D28: 2.864493 | E28: 3.1854246 | F28: 2.8972711
A29: %_PESO | B29: 36.811024 | C29: 51.574803 | D29: 24.409449 | E29: -23.228346 | F29: 10.433071 | G29: 100
A30: DA | B30: 35.23622 | C30: 39.76378 | D30: 24.409449 | E30: -11.417323 | F30: 12.007874
A31: Diferencia | B31: 1.5748031 | C31: 11.811024 | D31: 0 | E31: -11.811024 | F31: -1.5748031
A33: A2 | B33: 1 | C33: 2 | D33: 3 | E33: 4 | F33: 5 | G33: SUMA | H33: MEDIA | I33: DT | J33: %_PESO
A34: 1 | B34: 3.16 | C34: -0.27 | D34: 0 | E34: -2.57 | F34: -3.21 | G34: -2.89 | H34: -0.578 | I34: 2.5148101 | J34: 17.751843
A35: 2 | B35: -0.27 | C35: 0 | D35: 3.16 | E35: -3.02 | F35: -2.57 | G35: -2.7 | H35: -0.54 | I35: 2.4660596 | J35: 16.584767
A36: 3 | B36: 0 | C36: 3.16 | D36: -0.27 | E36: -3.21 | F36: -2.72 | G36: -3.04 | H36: -0.608 | I36: 2.5452249 | J36: 18.673219
A37: 4 | B37: -0.63 | C37: -3.03 | D37: -3.21 | E37: 3.16 | F37: -0.27 | G37: -3.98 | H37: -0.796 | I37: 2.5870988 | J37: 24.447174
A38: 5 | B38: -3.21 | C38: -0.63 | D38: -2.72 | E38: -0.27 | F38: 3.16 | G38: -3.67 | H38: -0.734 | I38: 2.5230993 | J38: 22.542998
A39: T_COL | B39: -0.95 | C39: -0.77 | D39: -3.04 | E39: -5.91 | F39: -5.61 | G39: -16.28
A40: Media_C | B40: -0.19 | C40: -0.154 | D40: -0.608 | E40: -1.182 | F40: -1.122
A41: DT_C | B41: 2.2682041 | C41: 2.2089432 | D41: 2.5452249 | E41: 2.6973265 | F41: 2.6491263
A42: %_PESO | B42: 5.8353808 | C42: 4.7297297 | D42: 18.673219 | E42: 36.302211 | F42: 34.459459 | G42: 100
A43: DA | B43: 17.751843 | C43: 16.584767 | D43: 18.673219 | E43: 24.447174 | F43: 22.542998
A44: Diferencia | B44: -11.916462 | C44: -11.855037 | D44: 0 | E44: 11.855037 | F44: 11.916462
A46: A3 | B46: 1 | C46: 2 | D46: 3 | E46: 4 | F46: 5 | G46: SUMA | H46: MEDIA | I46: DT | J46: %_PESO
...

Sheet 5.PRISMAS
C1: 1G1T1C PRISMAS RELACIONALES Y MATRICES DE DIFRACCIÓN 9x9
G2: Matriz ID: | H2: 1g1t1c (G2-T1-C1)
G3: Etapa: | H3: T1 - Diagnóstico Base | K3: Proyecto: | L3: Dossier Analítico NEX_ORD
C4: SIMULACIÓN IN SILICO Datos Anonimizados | G4: Motor Core: | H4: NEX_ORD Platinum v6.0 | K4: Analizado: | L4: 260829_154156
G5: Path Audit: | H5: .../05_Output/FULL_TABLES_1g1t1c.xlsx | K5: Protocolo: | L5: DOI 10.5281/zenodo.189416.1
A7: ► 5.01 MATRIZ DE DIFRACCIÓN NETA 1 (9x9): ASIMETRÍA DE FLUIDO NETO (SRC - SDA)
A8: Figura / Eje | B8: <Ee> | C8: <Ee! | D8: <Ee] | E8: <E?> | F8: <E?! | G8: <E?] | H8: <Er> | I8: <Er! | J8: <Er]
A9: <Ee> | B9: -0.01 | C9: 0.146 | D9: -0.166 | E9: -0.77 | F9: -0.424 | G9: -0.01 | H9: 0.146 | I9: -0.166 | J9: -0.77
A10: <Ee! | B10: -0.094 | C10: 0.062 | D10: -0.25 | E10: -0.854 | F10: -0.508 | G10: -0.094 | H10: 0.062 | I10: -0.25 | J10: -0.854
A11: <Ee] | B11: 0.13 | C11: 0.286 | D11: -0.026 | E11: -0.63 | F11: -0.284 | G11: 0.13 | H11: 0.286 | I11: -0.026 | J11: -0.63
A12: <E?> | B12: 0.682 | C12: 0.838 | D12: 0.526 | E12: -0.078 | F12: 0.268 | G12: 0.682 | H12: 0.838 | I12: 0.526 | J12: -0.078
A13: <E?! | B13: 0.382 | C13: 0.538 | D13: 0.226 | E13: -0.378 | F13: -0.032 | G13: 0.382 | H13: 0.538 | I13: 0.226 | J13: -0.378
A14: <E?] | B14: -0.01 | C14: 0.146 | D14: -0.166 | E14: -0.77 | F14: -0.424 | G14: -0.01 | H14: 0.146 | I14: -0.166 | J14: -0.77
A15: <Er> | B15: -0.094 | C15: 0.062 | D15: -0.25 | E15: -0.854 | F15: -0.508 | G15: -0.094 | H15: 0.062 | I15: -0.25 | J15: -0.854
A16: <Er! | B16: 0.13 | C16: 0.286 | D16: -0.026 | E16: -0.63 | F16: -0.284 | G16: 0.13 | H16: 0.286 | I16: -0.026 | J16: -0.63
A17: <Er] | B17: 0.682 | C17: 0.838 | D17: 0.526 | E17: -0.078 | F17: 0.268 | G17: 0.682 | H17: 0.838 | I17: 0.526 | J17: -0.078
A20: ► 5.02 MATRIZ DE DIFRACCIÓN BRUTA 2 (9x9): ASIMETRÍA DE FLUIDO BRUTO (BRC - BDA)
A21: Figura / Eje | B21: <Ee> | C21: <Ee! | D21: <Ee] | E21: <E?> | F21: <E?! | G21: <E?] | H21: <Er> | I21: <Er! | J21: <Er]
A22: <Ee> | B22: 0.01 | C22: -0.146 | D22: 0.166 | E22: 0.77 | F22: 0.424 | G22: 0.01 | H22: -0.146 | I22: 0.166 | J22: 0.77
A23: <Ee! | B23: 0.094 | C23: -0.062 | D23: 0.25 | E23: 0.854 | F23: 0.508 | G23: 0.094 | H23: -0.062 | I23: 0.25 | J23: 0.854
A24: <Ee] | B24: -0.13 | C24: -0.286 | D24: 0.026 | E24: 0.63 | F24: 0.284 | G24: -0.13 | H24: -0.286 | I24: 0.026 | J24: 0.63
A25: <E?> | B25: -0.682 | C25: -0.838 | D25: -0.526 | E25: 0.078 | F25: -0.268 | G25: -0.682 | H25: -0.838 | I25: -0.526 | J25: 0.078
A26: <E?! | B26: -0.382 | C26: -0.538 | D26: -0.226 | E26: 0.378 | F26: 0.032 | G26: -0.382 | H26: -0.538 | I26: -0.226 | J26: 0.378
A27: <E?] | B27: 0.01 | C27: -0.146 | D27: 0.166 | E27: 0.77 | F27: 0.424 | G27: 0.01 | H27: -0.146 | I27: 0.166 | J27: 0.77
A28: <Er> | B28: 0.094 | C28: -0.062 | D28: 0.25 | E28: 0.854 | F28: 0.508 | G28: 0.094 | H28: -0.062 | I28: 0.25 | J28: 0.854
A29: <Er! | B29: -0.13 | C29: -0.286 | D29: 0.026 | E29: 0.63 | F29: 0.284 | G29: -0.13 | H29: -0.286 | I29: 0.026 | J29: 0.63
A30: <Er] | B30: -0.682 | C30: -0.838 | D30: -0.526 | E30: 0.078 | F30: -0.268 | G30: -0.682 | H30: -0.838 | I30: -0.526 | J30: 0.078
A33: ► 5.03 MATRIZ DE DIFRACCIÓN DE EXPECTATIVAS 3 (9x9): DESCALCE DE SINTONÍA (A4 - A1)
A34: Figura / Eje | B34: <Ee> | C34: <Ee! | D34: <Ee] | E34: <E?> | F34: <E?! | G34: <E?] | H34: <Er> | I34: <Er! | J34: <Er]
A35: <Ee> | B35: 0.016 | C35: 0.084 | D35: -0.112 | E35: -0.538 | F35: -0.252 | G35: 0.016 | H35: 0.084 | I35: -0.112 | J35: -0.538
A36: <Ee! | B36: -0.03 | C36: 0.038 | D36: -0.158 | E36: -0.584 | F36: -0.298 | G36: -0.03 | H36: 0.038 | I36: -0.158 | J36: -0.584
A37: <Ee] | B37: 0.126 | C37: 0.194 | D37: -0.002 | E37: -0.428 | F37: -0.142 | G37: 0.126 | H37: 0.194 | I37: -0.002 | J37: -0.428
A38: <E?> | B38: 0.49 | C38: 0.558 | D38: 0.362 | E38: -0.064 | F38: 0.222 | G38: 0.49 | H38: 0.558 | I38: 0.362 | J38: -0.064
A39: <E?! | B39: 0.252 | C39: 0.32 | D39: 0.124 | E39: -0.302 | F39: -0.016 | G39: 0.252 | H39: 0.32 | I39: 0.124 | J39: -0.302
A40: <E?] | B40: 0.016 | C40: 0.084 | D40: -0.112 | E40: -0.538 | F40: -0.252 | G40: 0.016 | H40: 0.084 | I40: -0.112 | J40: -0.538
A41: <Er> | B41: -0.03 | C41: 0.038 | D41: -0.158 | E41: -0.584 | F41: -0.298 | G41: -0.03 | H41: 0.038 | I41: -0.158 | J41: -0.584
A42: <Er! | B42: 0.126 | C42: 0.194 | D42: -0.002 | E42: -0.428 | F42: -0.142 | G42: 0.126 | H42: 0.194 | I42: -0.002 | J42: -0.428
A43: <Er] | B43: 0.49 | C43: 0.558 | D43: 0.362 | E43: -0.064 | F43: 0.222 | G43: 0.49 | H43: 0.558 | I43: 0.362 | J43: -0.064
A46: ► 5.04 PRISMA INDIVIDUAL 1 (N x 9) | P46: ► 5.10 RESUMEN SÍNTESIS DE PRISMAS TOTALES
A48: PRISMA1 | B48: <E.. | C48: <¿.. | D48: <R.. | E48: ¡E.. | F48: ¡¿.. | G48: ¡R.. | H48: [E.. | I48: [¿.. | J48: [R.. | K48: SUMA | L48: MEDIA | M48: DT | N48: %_PESO | P48: RESUMEN | Q48: SUMA | R48: MEDIA | S48: DT | T48: %_PESO
...

Sheet 6.Reciprocidad
C1: 1G1T1C RECIPROCIDAD DE FIGURAS RELACIONALES MÚTUAS
G2: Matriz ID: | H2: 1g1t1c (G2-T1-C1)
G3: Etapa: | H3: T1 - Diagnóstico Base | K3: Proyecto: | L3: Dossier Analítico NEX_ORD
C4: SIMULACIÓN IN SILICO Datos Anonimizados | G4: Motor Core: | H4: NEX_ORD Platinum v6.0 | K4: Analizado: | L4: 260829_154156
G5: Path Audit: | H5: .../05_Output/FULL_TABLES_1g1t1c.xlsx | K5: Protocolo: | L5: DOI 10.5281/zenodo.189416.1
A8: ► 6.00 RESUMEN SÍNTESIS DE VALENCIAS MÚTUAS Y CALIBRACIÓN DE DENSIDAD SDR
A9: Métrica / Valencia Mútua | B9: Símbolo Canónico | C9: Conteo / Valor Promedio | D9: % Total / Calibración
A10: Reciprocidad Positiva (Afinidad Mútua) | B10: Ee | C10: 0 | D10: 0
A11: Reciprocidad Neutra (Indiferencia Mútua) | B11: ¿? | C11: 0 | D11: 0
A12: Reciprocidad Negativa (Rechazo Mútuo) | B12: Rr | C12: 0 | D12: 0
A13: Centroide SDR (Masa Total de Figuras Recíprocas) | B13: μ_SDR | C13: -0.9128 | D13: 100
A16: ► 6.01 SÍNTESIS DE RECIPROCIDAD Y CENTROIDE SDR POR SUJETO
A17: ID_Sujeto | B17: Centroide SDR (Sujeto) | C17: Mútuos Positivos Ee (%) | D17: Mútuos Neutros ¿? (%) | E17: Mútuos Negativos Rr (%) | F17: Total Reciprocidad (%)
A18: 1 | B18: -0.068 | C18: 0 | D18: 0 | E18: 0 | F18: 0
A19: 2 | B19: 0.156 | C19: 0 | D19: 0 | E19: 0 | F19: 0
A20: 3 | B20: -0.72 | C20: 0 | D20: 0 | E20: 0 | F20: 0
A21: 4 | B21: -2.302 | C21: 0 | D21: 0 | E21: 0 | F21: 0
A22: 5 | B22: -1.63 | C22: 0 | D22: 0 | E22: 0 | F22: 0
A23: Media | B23: =AVERAGE(B18:B22) -> 0 | C23: =AVERAGE(C18:C22) -> 0 | D23: =AVERAGE(D18:D22) -> 0 | E23: =AVERAGE(E18:E22) -> 0 | F23: =AVERAGE(F18:F22) -> 0

Sheet 7.Variables
C1: 1G1T1C ► 7.01 CENTROIDES DE DENSIDAD POR MODALIDAD
G2: Matriz ID: | H2: 1g1t1c (G2-T1-C1)
G3: Etapa: | H3: T1 - Diagnóstico Base | K3: Proyecto: | L3: Dossier Analítico NEX_ORD
C4: SIMULACIÓN IN SILICO Datos Anonimizados | G4: Motor Core: | H4: NEX_ORD Platinum v6.0 | K4: Analizado: | L4: 260829_154156
G5: Path Audit: | H5: .../05_Output/FULL_TABLES_1g1t1c.xlsx | K5: Protocolo: | L5: DOI 10.5281/zenodo.189416.1
A7: ► 7.01 VARIABLES COMPLEMENTARIAS | P7: ► 7.02 DESCRIPCION DE VARIABLES COMPLEMENTARIAS
A9: VARIABLE | B9: Modalidad | C9: n_sujetos | D9: A1 | E9: A2 | F9: A3 | G9: A4 | H9: SDA | I9: SRC | J9: SDR | K9: BDA | L9: BRC | M9: BDR | N9: SINTONIA | P9: VAR | Q9: NOM | R9: N_mod | S9: 1 | T9: 2 | U9: 3
A12: ► 7.04 HISTOGRAMA DE DISTRIBUCION DE LAS VARIABLES COMPLEMENTARIAS EN EL GRUPO TOTAL
A13: Modalidad | B13: MIN | C13: VAL | D13: MAX
P15: VAR_
A16: ► 7.05 GRAFICA DE DISPERSION DE CENTROIDES DE LAS MODALIDADES EN EL GRUPO TOTAL | P16: 1
P17: 2
P18: 3
P19: 4
P20: 5

Sheet 8.AAG_D
C1: 1G1T1C ► 8.01 DISTRIBUCION DE ADJETIVOS (AAG)
G2: Matriz ID: | H2: 1g1t1c (G2-T1-C1)
G3: Etapa: | H3: T1 - Diagnóstico Base | K3: Proyecto: | L3: Dossier Analítico NEX_ORD
C4: SIMULACIÓN IN SILICO Datos Anonimizados | G4: Motor Core: | H4: NEX_ORD Platinum v6.0 | K4: Analizado: | L4: 260829_154156
G5: Path Audit: | H5: .../05_Output/FULL_TABLES_1g1t1c.xlsx | K5: Protocolo: | L5: DOI 10.5281/zenodo.189416.1
A7: ► 8.01 AAG DICOTOMICA DENSIDAD RELACIONAL
A9: Categoría | B9: + / - | C9: sujetos | D9: Valor Adjetivo | E9: A1 | F9: A2 | G9: A3 | H9: A4 | I9: SDA | J9: SRC | K9: SDR | L9: BDA | M9: BRC | N9: BDR | O9: SINTONIA
A10: +sx | B10: + | C10: 3 | E10: 0.24266667 | F10: -0.64 | G10: -0.65666667 | H10: 0.24233333 | I10: -0.39533333 | J10: -0.41233333 | K10: -0.81166667 | L10: 3.9413333 | M10: 3.9583333 | N10: 7.8996667 | O10: 1.6402593
A11: -sx | B11: - | C11: 2 | E11: 0.144 | F11: -0.668 | G11: -0.671 | H11: 0.1305 | I11: -0.522 | J11: -0.5375 | K11: -1.0645 | L11: 4.068 | M11: 4.0845 | N11: 8.1525 | O11: 1.6800556
A12: +ed | B12: + | C12: 2 | E12: -0.031 | F12: -0.9585 | G12: -0.9725 | H12: -0.038 | I12: -0.9875 | J12: -1.008 | K12: -2 | L12: 4.5335 | M12: 4.5545 | N12: 9.088 | O12: 1.8932222
A13: -ed | B13: - | C13: 3 | E13: 0.35933333 | F13: -0.44633333 | G13: -0.45566667 | H13: 0.35466667 | I13: -0.085 | J13: -0.098666667 | K13: -0.188 | L13: 3.631 | M13: 3.645 | N13: 7.276 | O13: 1.4981481
A14: +ec | B14: + | C14: 2 | E14: 0.095 | F14: -0.6865 | G14: -0.7025 | H14: 0.088 | I14: -0.5895 | J14: -0.612 | K14: -1.206 | L14: 4.1355 | M14: 4.1585 | N14: 8.294 | O14: 1.6925
A15: -ec | B15: - | C15: 3 | E15: 0.27533333 | F15: -0.62766667 | G15: -0.63566667 | H15: 0.27066667 | I15: -0.35033333 | J15: -0.36266667 | K15: -0.71733333 | L15: 3.8963333 | M15: 3.909 | N15: 7.8053333 | O15: 1.631963
A16: +edu | B16: + | C16: 2 | E16: 0.144 | F16: -0.668 | G16: -0.671 | H16: 0.1305 | I16: -0.522 | J16: -0.5375 | K16: -1.0645 | L16: 4.068 | M16: 4.0845 | N16: 8.1525 | O16: 1.6800556
A17: -edu | B17: - | C17: 3 | E17: 0.24266667 | F17: -0.64 | G17: -0.65666667 | H17: 0.24233333 | I17: -0.39533333 | J17: -0.41233333 | K17: -0.81166667 | L17: 3.9413333 | M17: 3.9583333 | N17: 7.8996667 | O17: 1.6402593
A18: +eco | B18: + | C18: 3 | E18: 0.27533333 | F18: -0.62766667 | G18: -0.63566667 | H18: 0.27066667 | I18: -0.35033333 | J18: -0.36266667 | K18: -0.71733333 | L18: 3.8963333 | M18: 3.909 | N18: 7.8053333 | O18: 1.631963
A19: -eco | B19: - | C19: 2 | E19: 0.095 | F19: -0.6865 | G19: -0.7025 | H19: 0.088 | I19: -0.5895 | J19: -0.612 | K19: -1.206 | L19: 4.1355 | M19: 4.1585 | N19: 8.294 | O19: 1.6925
A20: +fam | B20: + | C20: 2 | E20: 0.036 | F20: -0.7985 | G20: -0.81 | H20: 0.0285 | I20: -0.7605 | J20: -0.779 | K20: -1.544 | L20: 4.3065 | M20: 4.3255 | N20: 8.632 | O20: 1.796
A21: -fam | B21: - | C21: 3 | E21: 0.31466667 | F21: -0.553 | G21: -0.564 | H21: 0.31033333 | I21: -0.23633333 | J21: -0.25133333 | K21: -0.492 | L21: 3.7823333 | M21: 3.7976667 | N21: 7.58 | O21: 1.562963
A24: ► 8.02 TABLA DE DISTRIBUCION DE ADJETIVOS DEL AAG Y PROMEDIOS
A26: Adjetivo | B26: 1 | C26: 2 | D26: 3 | E26: 4 | F26: 5 | G26: Media | H26: DT
A27: sx | B27: 1 | C27: 0 | D27: 1 | E27: 0 | F27: 1 | G27: 0.6 | H27: 0.54772256
A28: ed | B28: 18 | C28: 19 | D28: 20 | E28: 21 | F28: 22 | G28: 20 | H28: 1.5811388
A29: ec | B29: 1 | C29: 0 | D29: 0 | E29: 1 | F29: 0 | G29: 0.4 | H29: 0.54772256
A30: edu | B30: 0 | C30: 1 | D30: 0 | E30: 1 | F30: 0 | G30: 0.4 | H30: 0.54772256
A31: eco | B31: 2 | C31: 3 | D31: 4 | E31: 2 | F31: 3 | G31: 2.8 | H31: 0.83666003
A32: fam | B32: 1 | C32: 2 | D32: 3 | E32: 4 | F32: 1 | G32: 2.2 | H32: 1.3038405
A35: ► 8.03 HISTOGRAMA DE DISTRIBUCION DE ADJETIVOS DEL AAG
A37: AAG | B37: Media | C37: DT
A38: sx | B38: ='8.AAG_D'!G27 -> 0 | C38: ='8.AAG_D'!H27 -> 0
A39: ed | B39: ='8.AAG_D'!G28 -> 0 | C39: ='8.AAG_D'!H28 -> 0
A40: ec | B40: ='8.AAG_D'!G29 -> 0 | C40: ='8.AAG_D'!H29 -> 0
A41: edu | B41: ='8.AAG_D'!G30 -> 0 | C41: ='8.AAG_D'!H30 -> 0
A42: eco | B42: ='8.AAG_D'!G31 -> 0 | C42: ='8.AAG_D'!H31 -> 0
A43: fam | B43: ='8.AAG_D'!G32 -> 0 | C43: ='8.AAG_D'!H32 -> 0
A47: ► 8.04 GRAFICO DE DISPERSION DE CENTROIDES DEL AAG DICOTOMIZADO EN SDA SRC
A49: +sx | B49: -0.39533333 | C49: -0.41233333
A50: -sx | B50: -0.522 | C50: -0.5375
A51: +ed | B51: -0.9875 | C51: -1.008
A52: -ed | B52: -0.085 | C52: -0.098666667
...

Sheet 9.AAG_Meta
C1: 1G1T1C ► 9.01 ANALISIS META-ADJETIVAL (AAG)
G2: Matriz ID: | H2: 1g1t1c (G2-T1-C1)
G3: Etapa: | H3: T1 - Diagnóstico Base | K3: Proyecto: | L3: Dossier Analítico NEX_ORD
C4: SIMULACIÓN IN SILICO Datos Anonimizados | G4: Motor Core: | H4: NEX_ORD Platinum v6.0 | K4: Analizado: | L4: 260829_154156
G5: Path Audit: | H5: .../05_Output/FULL_TABLES_1g1t1c.xlsx | K5: Protocolo: | L5: DOI 10.5281/zenodo.189416.1
A7: ► 9.01 AAG META
A8: Sujeto | B8: Dif | C8: n_sujeto | D8: edu | E8: eco | F8: fam
A9: 1 | B9: 1 | D9: 0 | E9: 2 | F9: 1
B10: a_de 1 | C10: 2 | D10: 0.5 | E10: 0.5 | F10: 0.5
B11: o_de 1 | C11: 2 | D11: 0.5 | E11: 0.5 | F11: 0.5
B12: a - o | D12: 0 | E12: 0 | F12: 0
A13: 2 | B13: 2 | D13: 1 | E13: 3 | F13: 2
B14: a_de 2 | C14: 3 | D14: -0.33333333 | E14: -0.33333333 | F14: -0.33333333
B15: o_de 2 | C15: 2 | D15: -0.5 | E15: -0.5 | F15: -0.5
B16: a - o | D16: 0.16666667 | E16: 0.16666667 | F16: 0.16666667
A17: 3 | B17: 3 | D17: 0 | E17: 4 | F17: 3
B18: a_de 3 | C18: 2 | D18: 0.5 | E18: -1.50* | F18: -1.50*
B19: o_de 3 | C19: 2 | D19: 0.5 | E19: -1.50* | F19: -1.50*
B20: a - o | D20: 0 | E20: 0 | F20: 0
A21: 4 | B21: 4 | D21: 1 | E21: 2 | F21: 4
B22: a_de 4 | C22: 2 | D22: -0.5 | E22: 0.5 | F22: -2.50*
B23: o_de 4 | C23: 2 | D23: -0.5 | E23: 0.5 | F23: -2.50*
B24: a - o | D24: 0 | E24: 0 | F24: 0
A25: 5 | B25: 5 | D25: 0 | E25: 3 | F25: 1
B26: a_de 5 | C26: 2 | D26: 0.5 | E26: -0.5 | F26: 0.5
B27: o_de 5 | C27: 2 | D27: 0.5 | E27: -0.5 | F27: 0.5
B28: a - o | D28: 0 | E28: 0 | F28: 0

Sheet 9.AAG_Meta_Charts
C1: 1G1T1C ► 9.02 Histogramas AAG Meta
G2: Matriz ID: | H2: 1g1t1c (G2-T1-C1)
G3: Etapa: | H3: T1 - Diagnóstico Base | K3: Proyecto: | L3: Dossier Analítico NEX_ORD
C4: SIMULACIÓN IN SILICO Datos Anonimizados | G4: Motor Core: | H4: NEX_ORD Platinum v6.0 | K4: Analizado: | L4: 260829_154156
G5: Path Audit: | H5: .../05_Output/FULL_TABLES_1g1t1c.xlsx | K5: Protocolo: | L5: DOI 10.5281/zenodo.189416.1

Sheet 11.CLUSTERS
C1: 1G1T1C ► 11.CLUSTERS
G2: Matriz ID: | H2: 1g1t1c (G2-T1-C1)
G3: Etapa: | H3: T1 - Diagnóstico Base | K3: Proyecto: | L3: Dossier Analítico NEX_ORD
C4: SIMULACIÓN IN SILICO Datos Anonimizados | G4: Motor Core: | H4: NEX_ORD Platinum v6.0 | K4: Analizado: | L4: 260829_154156
G5: Path Audit: | H5: .../05_Output/FULL_TABLES_1g1t1c.xlsx | K5: Protocolo: | L5: DOI 10.5281/zenodo.189416.1
A7: ► 11.01 CLUSTERS | F7: ► 11.02 CLUSTERS DENSIDADES SDA / SRC
A9: ID_Sujeto | B9: K=2 | C9: K=3 | D9: K=4 | F9: ID_Sujeto | G9: K2_SDA | H9: K2_SRC | I9: K3_SDA | J9: K3_SRC | K9: K4_SDA | L9: K4_SRC
A10: 1 | B10: 1 | C10: 1 | D10: 1 | F10: 1 | G10: -0.64128852 | H10: -0.67319987 | I10: -0.64128852 | J10: -0.67319987 | K10: -0.33827253 | L10: -0.35331473
A11: 5 | B11: 1 | C11: 1 | D11: 2 | F11: 5 | G11: -0.64128852 | H11: -0.67319987 | I11: -0.64128852 | J11: -0.67319987 | K11: -0.94430451 | L11: -0.993085
A12: 2 | B12: 2 | C12: 2 | D12: 3 | F12: 2 | G12: -0.72342006 | H12: -0.74503999 | I12: -0.38177633 | J12: -0.35519384 | K12: -0.38177633 | L12: -0.35519384
A13: 3 | B13: 2 | C13: 2 | D13: 3 | F13: 3 | G13: -0.72342006 | H13: -0.74503999 | I13: -0.38177633 | J13: -0.35519384 | K13: -0.38177633 | L13: -0.35519384
A14: 4 | B14: 2 | C14: 3 | D14: 4 | F14: 4 | G14: -0.72342006 | H14: -0.74503999 | I14: -1.4067075 | J14: -1.5247323 | K14: -1.4067075 | L14: -1.5247323
A18: ► 11.03 DENDROGRAMA (CAJ)
A45: ► 11.04 SUBGRUPOS - TAXONOMÍA DE GRUPALIDADES
A47: TIPO DE GRUPALIDAD | E47: INDICADORES CLAVE (NEX_ORD 2026)
A48: 1. LA CLASE CRISTALINA (Grupalidad Integrada) | E48: Recl_E ↑↑, TrS_pE ↑↑, FaP_E ↓↓ Alta cohesión en los K-clusters principales. Grupo sano y transparente.
A50: 2. EL ARCHIPIÉLAGO (Grupalidad Fragmentada) | E50: Recl_E ↑, OpS_E ↑ Presencia de subgrupos múltiples densos pero aislados (N_GRUMOS > 3). Faltan puentes.
A52: 3. LA NIEBLA COGNITIVA (Grupalidad Disociada) | E52: FaP_E ↑↑, TrS_pE ↓↓ Repulsiones Activas (R) dispersas y bajas, pero [R] (Percibidas) difusas. Falsas percepciones dominan.
A54: 4. EL AGUJERO NEGRO (Grupalidad Conflictiva) | E54: IS ↑↑, SS ↓↓, Recl_R ↑↑ Tensión Sociométrica Alta. Alta Reciprocidad en Relegamientos. Conflictividad estructural.
A58: ► 11.05 ESCÁNER DE ESCALABILIDAD (REDES DE SINTONÍA Y NODOS PUENTE)
A60: RANKING DE NÚCLEOS DENSOS (Facciones Solapadas)
A61: Tam (k) | B61: Opción | C61: SDR Interna | D61: Integrantes (Nodos Puente)
A62: 2 | B62: Top 1 | C62: 5.308 | D62: 4, 5
A63: 2 | B63: Top 2 | C63: 5 | D63: 2, 3
A64: 2 | B64: Top 3 | C64: 3.257 | D64: 1, 4
A65: 3 | B65: Top 1 | C65: 2.654 | D65: 1, 2, 3
A66: 3 | B66: Top 2 | C66: 1.153 | D66: 2, 3, 5
A67: 3 | B67: Top 3 | C67: 0.754 | D67: 1, 4, 5
A68: 4 | B68: Top 1 | C68: 0.41 | D68: 1, 2, 3, 5
A69: 4 | B69: Top 2 | C69: 0.228 | D69: 1, 2, 3, 4
A70: 4 | B70: Top 3 | C70: -0.181 | D70: 2, 3, 4, 5
A71: 5 | B71: Top 1 | C71: -0.352 | D71: 1, 2, 3, 4, 5
A73: CODO DE SATURACIÓN DETECTADO EN k=3 SUJETOS.
A76: ► 11.06 SINTONÍA GRUPAL (PG-S) Y CLASIFICACIÓN DE NODOS
A78: ÍNDICE DE RESONANCIA RELACIONAL (IRR): | E78: 1.82
A80: ID Sujeto | B80: Rol Estructural (PG-S)
A81: 1 | B81: Nodo Puente (Pivote)
A82: 2 | B82: Nodo Puente (Pivote)
A83: 3 | B83: Nodo Puente (Pivote)
A84: 4 | B84: Nodo de Anclaje (Resistencia)
...

Sheet 12.INDICES
C1: 1G1T1C ► 12.INDICES
G2: Matriz ID: | H2: 1g1t1c (G2-T1-C1)
G3: Etapa: | H3: T1 - Diagnóstico Base | K3: Proyecto: | L3: Dossier Analítico NEX_ORD
C4: SIMULACIÓN IN SILICO Datos Anonimizados | G4: Motor Core: | H4: NEX_ORD Platinum v6.0 | K4: Analizado: | L4: 260829_154156
G5: Path Audit: | H5: .../05_Output/FULL_TABLES_1g1t1c.xlsx | K5: Protocolo: | L5: DOI 10.5281/zenodo.189416.1
A7: ► 12.01 INDICES GRUPALES TRADICIONALES
A9: IND | C9: Numerador | D9: Denominador | E9: Grupo | F9: 1 | G9: 2 | H9: 3 | I9: 4 | J9: 5
A10: I1 | B10: percep_E | C10: <. | D10: n | F10: 0.25 | G10: 0.5 | H10: 0.25 | I10: 0.25 | J10: 0.25
A11: I2 | B11: Elección | C11: E. | D11: n | F11: 0.5 | G11: 0.75 | H11: 0.5 | I11: 0.5 | J11: 0.5
A12: I3 | B12: Repulsión | C12: R. | D12: n | F12: 0.5 | G12: 0.5 | H12: 0.5 | I12: 0.5 | J12: 0.5
A13: I4 | B13: percep_R | C13: [. | D13: n | F13: 0.25 | G13: 0.25 | H13: 0.25 | I13: 0.25 | J13: 0.25
A14: I5 | B14: Recl_pE | C14: <.> | D14: <. | F14: 0.775 | G14: 0.85 | H14: 0.775 | I14: 0.775 | J14: 0.775
A15: I6 | B15: Recl_E | C15: Ee | D15: E. | F15: 0.85 | G15: 0.925 | H15: 0.85 | I15: 0.85 | J15: 0.85
A16: I7 | B16: Recl_R | C16: Rr | D16: R. | F16: 0.5 | G16: 0.5 | H16: 0.85 | I16: 0.85 | J16: 0.85
A17: I8 | B17: Recl_pR | C17: [.] | D17: [. | F17: 0.775 | G17: 0.075 | H17: 0.775 | I17: 0.775 | J17: 0.775
A18: I9 | B18: REP_E | C18: <.e | D18: < | F18: 0.775 | G18: 0.85 | H18: 0.775 | I18: 0.775 | J18: 0.775
A19: I10 | B19: REP_pE | C19: <.e | D19: e | F19: 0.5 | G19: 0.69166667 | H19: 0.5 | I19: 0.5 | J19: 0.5
A20: I11 | B20: REP_pR | C20: [.r | D20: r
A21: I12 | B21: REP_R | C21: [.r | D21: [
A22: I13 | B22: TrS_pE | C22: E.> | D22: > | F22: 0.5 | G22: 0.69166667 | H22: 0.5 | I22: 0.5 | J22: 0.5
A23: I14 | B23: TrS_E | C23: E.> | D23: E. | F23: 0.775 | G23: 0.85 | H23: 0.775 | I23: 0.775 | J23: 0.775
A24: I15 | B24: TrS_R | C24: R.] | D24: R.
A25: I16 | B25: TsS_pR | C25: R.] | D25: ]
A26: I17 | B26: FaP_pE | C26: <.r | D26: <.
A27: I18 | B27: FaP_pR | C27: ].e | D27: [.
A28: I19 | B28: OpS_pE | C28: <]/< | F28: 0.075 | G28: 0.15 | H28: 0.075 | I28: 0.075 | J28: 0.075
A29: I20 | B29: OpS_E | C29: E.r | D29: E. | F29: 0.15 | G29: 0.225 | H29: 0.15 | I29: 0.15 | J29: 0.15
A30: I21 | B30: OpS_R | C30: R.e | D30: R. | F30: 0.15 | G30: 0.15 | H30: 0.15 | I30: 0.15 | J30: 0.15
A31: I22 | B31: OpS_pR | C31: [>]/[ | F31: 0.075 | G31: 0.075 | H31: 0.075 | I31: 0.075 | J31: 0.075
A32: I23 | B32: SS | C32: e++>+r+ | D32: e++>+r+ | F32: 0.25 | G32: 0.5 | H32: 0 | I32: -0.25 | J32: -0.25
A33: I24 | B33: LID1 | C33: LIDERAZGO
A34: I25 | B34: LID2 | C34: LIDERAZGO
A35: I26 | B35: PoD1 | C35: PODER | F35: 0 | G35: 0 | H35: 0 | I35: 0 | J35: 0
A36: I27 | B36: PoD2 | C36: PODER | F36: 0 | G36: 0 | H36: 0 | I36: 0 | J36: 0
A37: I28 | B37: DIAG | C37: DIAG
A38: I29 | B38: SIG_B | C38: SIG_B
A39: I30 | B39: CRI | C39: CRI
A40: I31 | B40: K_INF | C40: K_INF
A43: ► 12.02 INDICES MORENO DESCRIPCION
A44: ID | B44: Sigla (DA/REC) | C44: Descripcion | D44: formula | E44: Rango
...

Sheet 10.PCA_coord
C1: 1G1T1C ► 10.01 PCA_COORD
G2: Matriz ID: | H2: 1g1t1c (G2-T1-C1)
G3: Etapa: | H3: T1 - Diagnóstico Base | K3: Proyecto: | L3: Dossier Analítico NEX_ORD
C4: SIMULACIÓN IN SILICO Datos Anonimizados | G4: Motor Core: | H4: NEX_ORD Platinum v6.0 | K4: Analizado: | L4: 260829_154156
G5: Path Audit: | H5: .../05_Output/FULL_TABLES_1g1t1c.xlsx | K5: Protocolo: | L5: DOI 10.5281/zenodo.189416.1
A7: ► 10.01 Coordenadas e inercias FILAS ACTIVAS | R7: ► TABLA EXTRAC. DATOS ORIGINALES (SDR)
A9: ID_Sujeto | B9: En 1 | E9: En 2 | H9: En 3 | K9: En 4 | N9: En 5 | R9: Sujeto | S9: 1 | T9: 2 | U9: 3 | V9: 4 | W9: 5
B10: COR | C10: CTR | D10: COS | E10: COR | F10: CTR | G10: COS | H10: COR | I10: CTR | J10: COS | K10: COR | L10: CTR | M10: COS | N10: COR | O10: CTR | P10: COS | R10: 1 | S10: 15.2 | T10: 1.98 | U10: 0 | V10: -4.7 | W10: -12.82
A11: 1 | B11: -0.44242038 | C11: 9.1422714 | D11: 44.962054 | E11: 0.47271406 | F11: 34.927587 | G11: 51.330196 | H11: 0.025929989 | I11: 0.2726731 | J11: 0.15444738 | K11: -0.12437357 | L11: 34.240993 | M11: 3.5533019 | R11: 2 | S11: 1.98 | T11: 0 | U11: 15.2 | V11: -11.7 | W11: -4.7
A12: 2 | B12: -0.50150725 | C12: 11.953319 | D12: 59.414096 | E12: -0.19125487 | F12: 5.8176391 | G12: 8.640922 | H12: -0.36429287 | I12: 54.763246 | J12: 31.349917 | K12: 0.050189693 | L12: 5.6737399 | M12: 0.59506463 | R12: 3 | S12: 0 | T12: 15.2 | U12: 1.98 | V12: -12.82 | W12: -7.96
A13: 3 | B13: -0.58953294 | C13: 15.404427 | D13: 68.059498 | E13: -0.20231236 | F13: 6.0710233 | G13: 8.0152561 | H13: 0.34008451 | I13: 44.509926 | J13: 22.648856 | K13: 0.0807338 | L13: 13.691356 | M13: 1.2763899 | R13: 4 | S13: -4.59 | T13: -11.26 | U13: -12.84 | V13: 15.2 | W13: 1.98
A14: 4 | B14: 0.99009747 | C14: 37.778634 | D14: 84.573399 | E14: 0.4075092 | F14: 21.416716 | G14: 14.326916 | H14: -0.0099030172 | I14: 0.032815513 | J14: 0.0084608296 | K14: 0.11246517 | L14: 23.101104 | M14: 1.0912242 | R14: 5 | S14: -12.82 | T14: -4.44 | U14: -8.07 | V14: 1.98 | W14: 15.2
A15: 5 | B15: 0.79209855 | C15: 25.721349 | D15: 71.93968 | E15: -0.48120136 | F15: 31.767035 | G15: 26.549953 | H15: 0.034404982 | I15: 0.42133909 | J15: 0.13572278 | K15: -0.10949395 | L15: 23.292806 | M15: 1.3746442
A18: ► 10.02 Coordenadas e inercias COLUMNAS ACTIVAS
A20: ID_Sujeto | B20: En 1 | E20: En 2 | H20: En 3 | K20: En 4 | N20: En 5
B21: COR | C21: CTR | D21: COS | E21: COR | F21: CTR | G21: COS | H21: COR | I21: CTR | J21: COS | K21: COR | L21: CTR | M21: COS | N21: COR | O21: CTR | P21: COS
A22: 1 | B22: -0.44374053 | C22: 9.2127531 | D22: 45.192232 | E22: 0.47190514 | F22: 34.868105 | G22: 51.111074 | H22: -0.026258581 | I22: 0.28010929 | J22: 0.15825159 | K22: -0.12416617 | L22: 34.18567 | M22: 3.5384427
A23: 2 | B23: -0.47907163 | C23: 11.02524 | D23: 57.358907 | E23: -0.18594928 | F23: 5.5585798 | G23: 8.6414967 | H23: 0.36543636 | I23: 55.701187 | J23: 33.37517 | K23: 0.049985114 | L23: 5.6881993 | M23: 0.62442652
A24: 3 | B24: -0.60319977 | C24: 16.092338 | D24: 69.204684 | E24: -0.20489874 | F24: 6.2138834 | G24: 7.9853093 | H24: -0.3365858 | I24: 43.505302 | J24: 21.547889 | K24: 0.081459797 | L24: 13.908803 | M24: 1.2621175
A25: 4 | B25: 0.99981232 | C25: 38.136174 | D25: 84.673327 | E25: 0.41021468 | F25: 21.483758 | G25: 14.253846 | H25: 0.0029034349 | I25: 0.0027924031 | J25: 0.00071405857 | K25: 0.11250333 | L25: 22.884276 | M25: 1.0721126
A26: 5 | B26: 0.79025878 | C26: 25.533494 | D26: 71.703581 | E26: -0.48266971 | F26: 31.875674 | G26: 26.748676 | H26: -0.037925519 | I26: 0.51060896 | J26: 0.16514493 | K26: -0.10973542 | L26: 23.333052 | M26: 1.3825978

Sheet 13.Difracción
C1: 1G1T1C Difracción
G2: Matriz ID: | H2: 1g1t1c (G2-T1-C1)
G3: Etapa: | H3: T1 - Diagnóstico Base | K3: Proyecto: | L3: Dossier Analítico NEX_ORD
C4: SIMULACIÓN IN SILICO Datos Anonimizados | G4: Motor Core: | H4: NEX_ORD Platinum v6.0 | K4: Analizado: | L4: 260829_154156
G5: Path Audit: | H5: .../05_Output/FULL_TABLES_1g1t1c.xlsx | K5: Protocolo: | L5: DOI 10.5281/zenodo.189416.1
A8: 13.01 Difracción
A11: ► 13.01 DENSIDAD NETA (SDR) - ENERGÍA ÚTIL | R11: ► 13.02
B12: e | C12: ? | D12: r | E12: > | F12: ! | G12: ] | H12: e> | I12: e! | J12: e] | K12: ?> | L12: ?! | M12: ?] | N12: r> | O12: r! | P12: r] | S12: e | T12: >
A13: E | B13: 4.69 | E13: 4.69 | H13: 4.69 | R13: E | S13: -3.22 | T13: -3.22
A14: ¿ | R14: <E | S14: -3.22 | T14: -3.22
A15: R | D15: -7.91 | G15: -7.91 | P15: -7.91
A16: < | B16: 4.69 | E16: 4.69 | H16: 4.69
A17: ¡
A18: [ | D18: -7.91 | G18: -7.91 | P18: -7.91
A19: <E | B19: 4.69 | E19: 4.69 | H19: 4.69
A20: <¿
A21: <R
A22: ¡E
A23: ¡¿
A24: ¡R
A25: [E
A26: [¿
A27: [R | D27: -7.91 | G27: -7.91 | P27: -7.91
A30: ► 13.03 FRECUENCIA DE IMPACTOS | R30: ► 13.04
B31: e | C31: ? | D31: r | E31: > | F31: ! | G31: ] | H31: e> | I31: e! | J31: e] | K31: ?> | L31: ?! | M31: ?] | N31: r> | O31: r! | P31: r] | S31: e | T31: >
A32: E | B32: 2 | E32: 2 | H32: 2 | R32: E | S32: 6 | T32: 6
A33: ¿ | R33: <E | S33: 6 | T33: 6
A34: R | D34: 4 | G34: 4 | P34: 4
A35: < | B35: 2 | E35: 2 | H35: 2
A36: ¡
A37: [ | D37: 4 | G37: 4 | P37: 4
A38: <E | B38: 2 | E38: 2 | H38: 2
A39: <¿
A40: <R
A41: ¡E
A42: ¡¿
A43: ¡R
A44: [E
A45: [¿
A46: [R | D46: 4 | G46: 4 | P46: 4
...

Sheet 14.Rejillas
C1: 1G1T1C Rejillas
G2: Matriz ID: | H2: 1g1t1c (G2-T1-C1)
G3: Etapa: | H3: T1 - Diagnóstico Base | K3: Proyecto: | L3: Dossier Analítico NEX_ORD
C4: SIMULACIÓN IN SILICO Datos Anonimizados | G4: Motor Core: | H4: NEX_ORD Platinum v6.0 | K4: Analizado: | L4: 260829_154156
G5: Path Audit: | H5: .../05_Output/FULL_TABLES_1g1t1c.xlsx | K5: Protocolo: | L5: DOI 10.5281/zenodo.189416.1
A8: ► 14.01 REJILLA TOPOGRAFICA DE FRECUENCIAS (15X15) | W8: ► 14.02 REJILLA TOPOGRAFICA DE DENSIDAD BRUTA (15X15)
B9: e | C9: ? | D9: r | E9: > | F9: ! | G9: ] | H9: e> | I9: e! | J9: e] | K9: ?> | L9: ?! | M9: ?] | N9: r> | O9: r! | P9: r] | Q9: Σ | X9: e | Y9: ? | Z9: r | AA9: > | AB9: ! | AC9: ] | AD9: e> | AE9: e! | AF9: e] | AG9: ?> | AH9: ?! | AI9: ?] | AJ9: r> | AK9: r! | AL9: r] | AM9: Σ
A10: E | B10: 2 | E10: 2 | H10: 2 | Q10: 6 | W10: E | X10: 4.69 | AA10: 4.69 | AD10: 4.69 | AM10: 14.07
A11: ¿ | W11: ¿
A12: R | D12: 4 | G12: 4 | P12: 4 | Q12: 12 | W12: R | Z12: 7.91 | AC12: 7.91 | AL12: 7.91 | AM12: 23.73
A13: < | B13: 2 | E13: 2 | H13: 2 | Q13: 6 | W13: < | X13: 4.69 | AA13: 4.69 | AD13: 4.69 | AM13: 14.07
A14: ¡ | W14: ¡
A15: [ | D15: 4 | G15: 4 | P15: 4 | Q15: 12 | W15: [ | Z15: 7.91 | AC15: 7.91 | AL15: 7.91 | AM15: 23.73
A16: <E | B16: 2 | E16: 2 | H16: 2 | Q16: 6 | W16: <E | X16: 4.69 | AA16: 4.69 | AD16: 4.69 | AM16: 14.07
A17: <¿ | W17: <¿
A18: <R | W18: <R
A19: ¡E | W19: ¡E
A20: ¡¿ | W20: ¡¿
A21: ¡R | W21: ¡R
A22: [E | W22: [E
A23: [¿ | W23: [¿
A24: [R | D24: 4 | G24: 4 | P24: 4 | Q24: 12 | W24: [R | Z24: 7.91 | AC24: 7.91 | AL24: 7.91 | AM24: 23.73
A25: Σ | B25: 6 | D25: 12 | E25: 6 | G25: 12 | H25: 6 | P25: 12 | Q25: 54 | W25: Σ | X25: 14.07 | Z25: 23.73 | AA25: 14.07 | AC25: 23.73 | AD25: 14.07 | AL25: 23.73 | AM25: 113.4
A29: ► 14.03 REJILLA FACTUAL - PRISMA 1 - ACTIVO (A4 x A1) | W29: ► 14.04 REJILLA FACTUAL - PRISMA 1 - ACTIVO (A4 x A1)
B30: E | C30: ¿ | D30: R | E30: < | F30: ¡ | G30: [ | H30: e | I30: ? | J30: r | K30: > | L30: ! | M30: ] | N30: Σ | X30: E | Y30: ¿ | Z30: R | AA30: < | AB30: ¡ | AC30: [ | AD30: e | AE30: ? | AF30: r | AG30: > | AH30: ! | AI30: ] | AJ30: Σ
A31: 1 | D31: 1 | G31: 1 | N31: 2 | W31: 1 | Z31: 1.98 | AC31: 1.98 | AJ31: 3.96
A32: 2 | B32: 1 | E32: 1 | N32: 2 | W32: 2 | X32: 2.35 | AA32: 2.35 | AJ32: 4.7
A33: 3 | B33: 1 | D33: 1 | E33: 1 | G33: 1 | N33: 4 | W33: 3 | X33: 2.35 | Z33: 1.98 | AA33: 2.35 | AC33: 1.98 | AJ33: 8.66
A34: 4 | D34: 1 | G34: 1 | N34: 2 | W34: 4 | Z34: 1.98 | AC34: 1.98 | AJ34: 3.96
A35: 5 | D35: 1 | G35: 1 | N35: 2 | W35: 5 | Z35: 1.98 | AC35: 1.98 | AJ35: 3.96
A36: Σ | B36: 2 | D36: 4 | E36: 2 | G36: 4 | N36: 12 | W36: Σ | X36: 4.7 | Z36: 7.92 | AA36: 4.7 | AC36: 7.92 | AJ36: 25.24
A40: ► 14.05 REJILLA FACTUAL - PRISMA 2 - PASIVO (A2 x A3) | W40: ► 14.06 REJILLA FACTUAL - PRISMA 2 - PASIVO (A2 x A3)
B41: E | C41: ¿ | D41: R | E41: < | F41: ¡ | G41: [ | H41: e | I41: ? | J41: r | K41: > | L41: ! | M41: ] | N41: Σ | X41: E | Y41: ¿ | Z41: R | AA41: < | AB41: ¡ | AC41: [ | AD41: e | AE41: ? | AF41: r | AG41: > | AH41: ! | AI41: ] | AJ41: Σ
A42: 1 | J42: 1 | M42: 1 | N42: 2 | W42: 1 | AF42: 1.98 | AI42: 1.98 | AJ42: 3.96
A43: 2 | H43: 1 | K43: 1 | N43: 2 | W43: 2 | AD43: 2.35 | AG43: 2.35 | AJ43: 4.7
A44: 3 | H44: 1 | J44: 1 | K44: 1 | M44: 1 | N44: 4 | W44: 3 | AD44: 2.35 | AF44: 1.98 | AG44: 2.35 | AI44: 1.98 | AJ44: 8.66
A45: 4 | J45: 1 | M45: 1 | N45: 2 | W45: 4 | AF45: 1.99 | AI45: 1.99 | AJ45: 3.98
A46: 5 | J46: 1 | M46: 1 | N46: 2 | W46: 5 | AF46: 1.98 | AI46: 1.98 | AJ46: 3.96
A47: Σ | H47: 2 | J47: 4 | K47: 2 | M47: 4 | N47: 12 | W47: Σ | AD47: 4.7 | AF47: 7.93 | AG47: 4.7 | AI47: 7.93 | AJ47: 25.26
A51: ► 14.07 REJILLA PERCEPTUAL - PRISMA 3 - EXTERNO (A4 x A2) | W51: ► 14.08 REJILLA PERCEPTUAL - PRISMA 3 - EXTERNO (A4 x A2)
...

Sheet 15.Difr_Prismas
C1: 1G1T1C Difr. Prismas
G2: Matriz ID: | H2: 1g1t1c (G2-T1-C1)
G3: Etapa: | H3: T1 - Diagnóstico Base | K3: Proyecto: | L3: Dossier Analítico NEX_ORD
C4: SIMULACIÓN IN SILICO Datos Anonimizados | G4: Motor Core: | H4: NEX_ORD Platinum v6.0 | K4: Analizado: | L4: 260829_154156
G5: Path Audit: | H5: .../05_Output/FULL_TABLES_1g1t1c.xlsx | K5: Protocolo: | L5: DOI 10.5281/zenodo.189416.1
A8: 15.01 PRISMA 1 - ACTIVO (A4 x A1)
A11: ► 15.01 DENSIDAD NETA (SDR) - PRISMA 1 - ACTIVO (A4 x A1) | W11: ► 15.02 FRECUENCIA DE IMPACTOS
B12: E | C12: ¿ | D12: R | E12: Σ | F12: < | G12: ¡ | H12: [ | I12: Σ | J12: e | K12: ? | L12: r | M12: Σ | N12: > | O12: ! | P12: ] | Q12: Σ | X12: E | Y12: ¿ | Z12: R | AA12: Σ | AB12: < | AC12: ¡ | AD12: [ | AE12: Σ | AF12: e | AG12: ? | AH12: r | AI12: Σ | AJ12: > | AK12: ! | AL12: ] | AM12: Σ
A13: 1 | D13: -1.98 | E13: -1.98 | H13: -1.98 | I13: -1.98 | W13: 1 | Z13: 1 | AA13: 1 | AD13: 1 | AE13: 1
A14: 2 | B14: 2.35 | E14: 2.35 | F14: 2.35 | I14: 2.35 | W14: 2 | X14: 1 | AA14: 1 | AB14: 1 | AE14: 1
A15: 3 | B15: 2.35 | D15: -1.98 | E15: 0.37 | F15: 2.35 | H15: -1.98 | I15: 0.37 | W15: 3 | X15: 1 | Z15: 1 | AA15: 2 | AB15: 1 | AD15: 1 | AE15: 2
A16: 4 | D16: -1.98 | E16: -1.98 | H16: -1.98 | I16: -1.98 | W16: 4 | Z16: 1 | AA16: 1 | AD16: 1 | AE16: 1
A17: 5 | D17: -1.98 | E17: -1.98 | H17: -1.98 | I17: -1.98 | W17: 5 | Z17: 1 | AA17: 1 | AD17: 1 | AE17: 1
A21: ► 15.03 DENSIDAD BRUTA (BDR) | W21: ► 15.04 DESGASTE TERMODINÁMICO
B22: E | C22: ¿ | D22: R | E22: Σ | F22: < | G22: ¡ | H22: [ | I22: Σ | J22: e | K22: ? | L22: r | M22: Σ | N22: > | O22: ! | P22: ] | Q22: Σ | X22: E | Y22: ¿ | Z22: R | AA22: Σ | AB22: < | AC22: ¡ | AD22: [ | AE22: Σ | AF22: e | AG22: ? | AH22: r | AI22: Σ | AJ22: > | AK22: ! | AL22: ] | AM22: Σ
A23: 1 | D23: 1.98 | E23: 1.98 | H23: 1.98 | I23: 1.98 | W23: 1
A24: 2 | B24: 2.35 | E24: 2.35 | F24: 2.35 | I24: 2.35 | W24: 2
A25: 3 | B25: 2.35 | D25: 1.98 | E25: 4.33 | F25: 2.35 | H25: 1.98 | I25: 4.33 | W25: 3
A26: 4 | D26: 1.98 | E26: 1.98 | H26: 1.98 | I26: 1.98 | W26: 4
A27: 5 | D27: 1.98 | E27: 1.98 | H27: 1.98 | I27: 1.98 | W27: 5
A32: 15.02 PRISMA 2 - PASIVO (A2 x A3)
A35: ► 15.05 DENSIDAD NETA (SDR) - PRISMA 2 - PASIVO (A2 x A3) | W35: ► 15.06 FRECUENCIA DE IMPACTOS
B36: E | C36: ¿ | D36: R | E36: Σ | F36: < | G36: ¡ | H36: [ | I36: Σ | J36: e | K36: ? | L36: r | M36: Σ | N36: > | O36: ! | P36: ] | Q36: Σ | X36: E | Y36: ¿ | Z36: R | AA36: Σ | AB36: < | AC36: ¡ | AD36: [ | AE36: Σ | AF36: e | AG36: ? | AH36: r | AI36: Σ | AJ36: > | AK36: ! | AL36: ] | AM36: Σ
A37: 1 | L37: -1.98 | M37: -1.98 | P37: -1.98 | Q37: -1.98 | W37: 1 | AH37: 1 | AI37: 1 | AL37: 1 | AM37: 1
A38: 2 | J38: 2.35 | M38: 2.35 | N38: 2.35 | Q38: 2.35 | W38: 2 | AF38: 1 | AI38: 1 | AJ38: 1 | AM38: 1
A39: 3 | J39: 2.35 | L39: -1.98 | M39: 0.37 | N39: 2.35 | P39: -1.98 | Q39: 0.37 | W39: 3 | AF39: 1 | AH39: 1 | AI39: 2 | AJ39: 1 | AL39: 1 | AM39: 2
A40: 4 | L40: -1.99 | M40: -1.99 | P40: -1.99 | Q40: -1.99 | W40: 4 | AH40: 1 | AI40: 1 | AL40: 1 | AM40: 1
A41: 5 | L41: -1.98 | M41: -1.98 | P41: -1.98 | Q41: -1.98 | W41: 5 | AH41: 1 | AI41: 1 | AL41: 1 | AM41: 1
A45: ► 15.07 DENSIDAD BRUTA (BDR) | W45: ► 15.08 DESGASTE TERMODINÁMICO
B46: E | C46: ¿ | D46: R | E46: Σ | F46: < | G46: ¡ | H46: [ | I46: Σ | J46: e | K46: ? | L46: r | M46: Σ | N46: > | O46: ! | P46: ] | Q46: Σ | X46: E | Y46: ¿ | Z46: R | AA46: Σ | AB46: < | AC46: ¡ | AD46: [ | AE46: Σ | AF46: e | AG46: ? | AH46: r | AI46: Σ | AJ46: > | AK46: ! | AL46: ] | AM46: Σ
A47: 1 | L47: 1.98 | M47: 1.98 | P47: 1.98 | Q47: 1.98 | W47: 1
A48: 2 | J48: 2.35 | M48: 2.35 | N48: 2.35 | Q48: 2.35 | W48: 2
A49: 3 | J49: 2.35 | L49: 1.98 | M49: 4.33 | N49: 2.35 | P49: 1.98 | Q49: 4.33 | W49: 3
A50: 4 | L50: 1.99 | M50: 1.99 | P50: 1.99 | Q50: 1.99 | W50: 4
A51: 5 | L51: 1.98 | M51: 1.98 | P51: 1.98 | Q51: 1.98 | W51: 5
A56: 15.03 PRISMA 3 - EXTERNO (A4 x A2)
A59: ► 15.09 DENSIDAD NETA (SDR) - PRISMA 3 - EXTERNO (A4 x A2) | W59: ► 15.10 FRECUENCIA DE IMPACTOS
B60: E | C60: ¿ | D60: R | E60: Σ | F60: < | G60: ¡ | H60: [ | I60: Σ | J60: e | K60: ? | L60: r | M60: Σ | N60: > | O60: ! | P60: ] | Q60: Σ | X60: E | Y60: ¿ | Z60: R | AA60: Σ | AB60: < | AC60: ¡ | AD60: [ | AE60: Σ | AF60: e | AG60: ? | AH60: r | AI60: Σ | AJ60: > | AK60: ! | AL60: ] | AM60: Σ
A61: 1 | H61: -1.98 | I61: -1.98 | L61: -1.98 | M61: -1.98 | W61: 1 | AD61: 1 | AE61: 1 | AH61: 1 | AI61: 1
A62: 2 | F62: 2.35 | I62: 2.35 | J62: 2.35 | M62: 2.35 | W62: 2 | AB62: 1 | AE62: 1 | AF62: 1 | AI62: 1
...

Sheet 16.Difrac_Resumen
C1: 1G1T1C Resumen Difracción
G2: Matriz ID: | H2: 1g1t1c (G2-T1-C1)
G3: Etapa: | H3: T1 - Diagnóstico Base | K3: Proyecto: | L3: Dossier Analítico NEX_ORD
C4: SIMULACIÓN IN SILICO Datos Anonimizados | G4: Motor Core: | H4: NEX_ORD Platinum v6.0 | K4: Analizado: | L4: 260829_154156
G5: Path Audit: | H5: .../05_Output/FULL_TABLES_1g1t1c.xlsx | K5: Protocolo: | L5: DOI 10.5281/zenodo.189416.1
A8: DIFRACCIÓN GLOBAL
A10: ► 16.01 DENSIDAD NETA (SDR) - ENERGÍA ÚTIL | F10: ► 16.02 FRECUENCIA DE IMPACTOS
B11: e | C11: > | D11: Σ | G11: e | H11: > | I11: Σ
A12: E | B12: -3.22 | C12: -3.22 | D12: -6.44 | F12: E | G12: 6 | H12: 6 | I12: 12
A13: <E | B13: -3.22 | C13: -3.22 | D13: -6.44 | F13: <E | G13: 6 | H13: 6 | I13: 12
A14: Σ | B14: -6.44 | C14: -6.44 | D14: -12.88 | F14: Σ | G14: 12 | H14: 12 | I14: 24
A16: ► 16.03 DENSIDAD BRUTA (BDR) - TRABAJO TOTAL | F16: ► 16.04 DESGASTE TERMODINÁMICO (BDR - |SDR|)
B17: e | C17: > | D17: Σ | G17: e | H17: > | I17: Σ
A18: E | B18: 12.6 | C18: 12.6 | D18: 25.2 | F18: E
A19: <E | B19: 12.6 | C19: 12.6 | D19: 25.2 | F19: <E
A20: Σ | B20: 25.2 | C20: 25.2 | D20: 50.4 | F20: Σ
A23: PRISMA 1 - ACTIVO (A4 x A1)
A25: ► 16.05 PRISMA 1 - ACTIVO (A4 x A1) (SDR) | F25: ► 16.06 PRISMA 1 - ACTIVO (A4 x A1) (FREQ)
B26: e | C26: > | D26: Σ | G26: e | H26: > | I26: Σ
A27: E | F27: E
A28: <E | F28: <E
A29: Σ | F29: Σ
A31: ► 16.07 PRISMA 1 - ACTIVO (A4 x A1) (BDR) | F31: ► 16.08 PRISMA 1 - ACTIVO (A4 x A1) (WEAR)
B32: e | C32: > | D32: Σ | G32: e | H32: > | I32: Σ
A33: E | F33: E
A34: <E | F34: <E
A35: Σ | F35: Σ
A38: PRISMA 2 - PASIVO (A2 x A3)
A40: ► 16.09 PRISMA 2 - PASIVO (A2 x A3) (SDR) | F40: ► 16.10 PRISMA 2 - PASIVO (A2 x A3) (FREQ)
B41: e | C41: > | D41: Σ | G41: e | H41: > | I41: Σ
A42: E | F42: E
A43: <E | F43: <E
A44: Σ | F44: Σ
A46: ► 16.11 PRISMA 2 - PASIVO (A2 x A3) (BDR) | F46: ► 16.12 PRISMA 2 - PASIVO (A2 x A3) (WEAR)
B47: e | C47: > | D47: Σ | G47: e | H47: > | I47: Σ
A48: E | F48: E
A49: <E | F49: <E
A50: Σ | F50: Σ
A53: PRISMA 3 - EXTERNO (A4 x A2)
A55: ► 16.13 PRISMA 3 - EXTERNO (A4 x A2) (SDR) | F55: ► 16.14 PRISMA 3 - EXTERNO (A4 x A2) (FREQ)
...

Sheet 17.Individual
C1: 1G1T1C 17.Individual
G2: Matriz ID: | H2: 1g1t1c (G2-T1-C1)
G3: Etapa: | H3: T1 - Diagnóstico Base | K3: Proyecto: | L3: Dossier Analítico NEX_ORD
C4: SIMULACIÓN IN SILICO Datos Anonimizados | G4: Motor Core: | H4: NEX_ORD Platinum v6.0 | K4: Analizado: | L4: 260829_154156
G5: Path Audit: | H5: .../05_Output/FULL_TABLES_1g1t1c.xlsx | K5: Protocolo: | L5: DOI 10.5281/zenodo.189416.1
A8: ► 17.01 FRECUENCIAS INDIVIDUALES (DA / RECIBE) | X8: ► 17.05 LEYENDA
C9: E | D9: ¿ | E9: R | F9: < | G9: ¡ | H9: [ | I9: Ee | J9: ¿? | K9: Rr | L9: <..> | M9: ¡..! | N9: [..] | O9: Er | P9: Re | Q9: <..] | R9: [..> | S9: <Ee> | T9: ¡¿?! | U9: [Rr] | X9: E | Y9: Elección
A10: 1 | B10: DA | X10: ¿ | Y10: Indiferencia
B11: RC | X11: R | Y11: Rechazo
A12: 2 | B12: DA | X12: < | Y12: Percepción de elección
B13: RC | X13: ¡ | Y13: Percepción de indiferencia
A14: 3 | B14: DA | X14: [ | Y14: Percepción de rechazo
B15: RC | X15: e | Y15: Elección recibida
A16: 4 | B16: DA | X16: ? | Y16: Indiferencia recibida
B17: RC | X17: r | Y17: Rechazo recibido
A18: 5 | B18: DA | X18: > | Y18: Percepción de elección recíproca
B19: RC | X19: ! | Y19: Percepción de indiferencia recíproca
X20: ] | Y20: Percepción de rechazo recíproca
X21: Ee | Y21: Elección mutuamente recíproca
A22: ► 17.02 INDICES INDIVIDUALES 01-16 (DA / RECIBE) | X22: Rr | Y22: Rechazo mutuamente recíproca
C23: I1 | D23: I2 | E23: I3 | F23: I4 | G23: I5 | H23: I6 | I23: I7 | J23: I8 | K23: I9 | L23: I10 | M23: I11 | N23: I12 | O23: I13 | P23: I14 | Q23: I15 | R23: I16 | X23: Er | Y23: Oposición Factual Interna: Er
A24: 1 | B24: DA | X24: Re | Y24: Oposición Factual Externa: Re
B25: RC | X25: <] | Y25: Oposición Perceptual Interna: <]
A26: 2 | B26: DA | X26: [> | Y26: Oposición Perceptual Externa: [>
B27: RC | X27: <Ee> | Y27: Elección mutua mutuamente percibida
A28: 3 | B28: DA | X28: [Rr] | Y28: Rechazo mutuo mutuamente percibido
B29: RC
A30: 4 | B30: DA
B31: RC | X31: ► 17.06 INDICES MODELO / DESCRIPCION
A32: 5 | B32: DA | X32: ID | Y32: Sigla | Z32: Descripción | AA32: Fórmula | AB32: Rango
B33: RC | X33: I1 | Y33: percep_E | Z33: EXPANSIVIDAD pE | AA33: < / n* | AB33: Rango [0, 1]
X34: I2 | Y34: Elección | Z34: EXPANSIVIDAD E | AA34: E / n* | AB34: Rango [0, 1]
X35: I3 | Y35: Repulsión | Z35: EXPANSIVIDAD R | AA35: R / n* | AB35: Rango [0, 1]
A36: ► 17.03 INDICES INDIVIDUALES 17-31 (DA / RECIBE) | X36: I4 | Y36: percep_R | Z36: EXPANSIVIDAD pR | AA36: [ / n* | AB36: Rango [0, 1]
C37: I17 | D37: I18 | E37: I19 | F37: I20 | G37: I21 | H37: I22 | I37: I23 | J37: I24 | K37: I25 | L37: I26 | M37: I27 | N37: I28 | O37: I29 | P37: I30 | Q37: I31 | X37: I5 | Y37: Real_pE | Z37: RECIPROCIDAD pE | AA37: <,> / < | AB37: Rango [0, 1]
A38: 1 | B38: DA | X38: I6 | Y38: Reci_E | Z38: RECIPROCIDAD E | AA38: Ee / E | AB38: Rango [0, 1]
B39: RC | X39: I7 | Y39: Reci_R | Z39: RECIPROCIDAD R | AA39: Rr / R | AB39: Rango [0, 1]
A40: 2 | B40: DA | X40: I8 | Y40: Real_pR | Z40: RECIPROCIDAD pR | AA40: [,] / [ | AB40: Rango [0, 1]
B41: RC | X41: I9 | Y41: REP_E | Z41: REALISMO PERCEPTUAL E | AA41: <,e / < | AB41: Rango [0, 1]
A42: 3 | B42: DA | X42: I10 | Y42: REP_pE | Z42: REALISMO PERCEPTUAL pE | AA42: <,e / e | AB42: Rango [0, 1]
...

Sheet 18.Análisis_Espectral_AGE
C1: 1G1T1C ► 18. ANÁLISIS ESPECTRAL GENERALIZADO (AGE - SVD & FOURIER)
G2: Matriz ID: | H2: 1g1t1c (G2-T1-C1)
G3: Etapa: | H3: T1 - Diagnóstico Base | K3: Proyecto: | L3: Dossier Analítico NEX_ORD
C4: SIMULACIÓN IN SILICO Datos Anonimizados | G4: Motor Core: | H4: NEX_ORD Platinum v6.0 | K4: Analizado: | L4: 260829_154156
G5: Path Audit: | H5: .../05_Output/FULL_TABLES_1g1t1c.xlsx | K5: Protocolo: | L5: DOI 10.5281/zenodo.189416.1
A7: ► 18.01 ESPECTRO DE AUTOVALORES SINGULARES (AGE - SVD)
A8: Modo_Espectral | B8: Autovalor_Singular (λ) | C8: Varianza_Explicada_% | D8: Varianza_Acumulada_%
A9: Modo 1 (λ_1) | B9: 15.3759 | C9: 85.97 | D9: 85.97
A10: Modo 2 (λ_2) | B10: 5.3318 | C10: 10.34 | D10: 96.31
A11: Modo 3 (λ_3) | B11: 2.5076 | C11: 2.29 | D11: 98.59
A12: Modo 4 (λ_4) | B12: 1.7002 | C12: 1.05 | D12: 99.65
A13: Modo 5 (λ_5) | B13: 0.9871 | C13: 0.35 | D13: 100
A16: ► 18.02 INDICADORES SINTÉTICOS DE LA RED ESPECTRAL
A17: Radio Espectral (λ_1) | B17: 15.3759 | C17: Brecha Espectral (λ_1 - λ_2) | D17: 10.0441
